<?xml version="1.0"?>
<robot name="panda" 
  xmlns:xacro="http://www.ros.org/wiki/xacro">
  <link name="base_link">
    <visual>
      <geometry>
        <mesh filename="link0.stl"/>
      </geometry>
      <material name="panda_white"/>
    </visual>
    <collision>
      <geometry>
        <mesh filename="link0.stl"/>
      </geometry>
      <material name="panda_white"/>
    </collision>
    <inertial>
      <mass value="2.92" />
      <origin xyz="-0.025566 -2.88e-05 0.057332" rpy="0 0 0" />
      <inertia ixx="0.00782229414331" ixy="-1.56191622996e-05" ixz="-0.00126005738123" iyy="0.0109027971813" iyz="1.08233858202e-05" izz="0.0102355503949" />
    </inertial>
  </link>

  <link name="panda_link1">
    <visual>
      <geometry>
        <mesh filename="link1.stl"/>
      </geometry>
      <material name="panda_white"/>
    </visual>
    <collision>
      <geometry>
        <mesh filename="link1.stl"/>
      </geometry>
      <material name="panda_white"/>
    </collision>
    <inertial>
      <mass value="2.74" />
      <origin xyz="0 -0.0324958 -0.0675818" rpy="0 0 0" />
      <inertia ixx="0.0180416958283" ixy="0.0" ixz="0.0" iyy="0.0159136071891" iyz="0.0046758424612" izz="0.00620690827127" />
    </inertial>
  </link>
  <joint name="panda_joint1" type="revolute">
    <safety_controller k_position="100.0" k_velocity="40.0" soft_lower_limit="-2.8973" soft_upper_limit="2.8973"/>
    <origin rpy="0 0 0" xyz="0 0 0.333"/>
    <parent link="base_link"/>
    <child link="panda_link1"/>
    <axis xyz="0 0 1"/>
    <limit effort="87" lower="-2.9671" upper="2.9671" velocity="2.1750"/>
    <controller k_t="2.5" k_s="0.1" k_p="1600.0" k_d="80.0"/>
    <properties inertia="2.95761" stiffness="26758" damping="1"/>
    <home value="0"/>
  </joint>

  <link name="panda_link2">
    <visual>
      <geometry>
        <mesh filename="link2.stl"/>
      </geometry>
      <material name="panda_white"/>
    </visual>
    <collision>
      <geometry>
        <mesh filename="link2.stl"/>
      </geometry>
      <material name="panda_white"/>
    </collision>
    <inertial>
      <mass value="2.74" />
      <origin xyz="0 -0.06861 0.0322285" rpy="0 0 0" />
      <inertia ixx="0.0182856182281" ixy="0.0" ixz="0.0" iyy="0.00621358421175" iyz="-0.00472844221905" izz="0.0161514346309" />
    </inertial>
  </link>
  <joint name="panda_joint2" type="revolute">
    <safety_controller k_position="100.0" k_velocity="40.0" soft_lower_limit="-1.7628" soft_upper_limit="1.7628"/>
    <origin rpy="-1.57079632679 0 0" xyz="0 0 0"/>
    <parent link="panda_link1"/>
    <child link="panda_link2"/>
    <axis xyz="0 0 1"/>
    <limit effort="87" lower="-1.8326" upper="1.8326" velocity="2.1750"/>
    <controller k_t="2.5" k_s="0.1" k_p="1600.0" k_d="80.0"/>
    <properties inertia="2.95761" stiffness="26758" damping="1"/>
    <home value="-1"/>
  </joint>

  <link name="panda_link3">
    <visual>
      <geometry>
        <mesh filename="link3.stl"/>
      </geometry>
      <material name="panda_white"/>
    </visual>
    <collision>
      <geometry>
        <mesh filename="link3.stl"/>
      </geometry>
      <material name="panda_white"/>
    </collision>
    <inertial>
      <mass value="2.38" />
      <origin xyz="0.0469893 0.0316374 -0.031704" rpy="0 0 0" />
      <inertia ixx="0.00771376630908" ixy="-0.00248490625138" ixz="-0.00332147581033" iyy="0.00989108008727" iyz="-0.00217796151484" izz="0.00811723558464" />
    </inertial>
  </link>
  <joint name="panda_joint3" type="revolute">
    <safety_controller k_position="100.0" k_velocity="40.0" soft_lower_limit="-2.8973" soft_upper_limit="2.8973"/>
    <origin rpy="1.57079632679 0 0" xyz="0 -0.316 0"/>
    <parent link="panda_link2"/>
    <child link="panda_link3"/>
    <axis xyz="0 0 1"/>
    <limit effort="87" lower="-2.9671" upper="2.9671" velocity="2.1750"/>
    <controller k_t="2.0" k_s="0.05" k_p="1600.0" k_d="80.0"/>
    <properties inertia="0.95992" stiffness="10957" damping="1"/>
    <home value="0"/>
  </joint>

  <link name="panda_link4">
    <visual>
      <geometry>
        <mesh filename="link4.stl"/>
      </geometry>
      <material name="panda_white"/>
    </visual>
    <collision>
      <geometry>
        <mesh filename="link4.stl"/>
      </geometry>
      <material name="panda_white"/>
    </collision>
    <inertial>
      <mass value="2.38" />
      <origin xyz="-0.0360446 0.0336853 0.031882" rpy="0 0 0" />
      <inertia ixx="0.00799663881132" ixy="0.00347095570217" ixz="-0.00241222942995" iyy="0.00825390705278" iyz="0.00235774044121" izz="0.0102515004345" />
    </inertial>
  </link>
  <joint name="panda_joint4" type="revolute">
    <safety_controller k_position="100.0" k_velocity="40.0" soft_lower_limit="-3.0718" soft_upper_limit="-0.0698"/>
    <origin rpy="1.57079632679 0 0" xyz="0.0825 0 0"/>
    <parent link="panda_link3"/>
    <child link="panda_link4"/>
    <axis xyz="0 0 1"/>
    <limit effort="87" lower="-3.1416" upper="0.0" velocity="2.1750"/>
    <controller k_t="2.0" k_s="0.05" k_p="1600.0" k_d="80.0"/>
    <properties inertia="0.95992" stiffness="10957" damping="1"/>
    <home value="-2"/>
  </joint>

  <material name="panda_white">
    <color rgba="1. 1. 1. 1."/>
  </material>
</robot>
